<?xml version="1.0"?>
<robot xmlns:xacro="http://www.ros.org/wiki/xacro">
  <xacro:macro name="drive_wheel" params="prefix x y z radius width mass">
    <link name="${prefix}_wheel_link">
      <visual>
        <origin xyz="0 0 0" rpy="1.5708 0 0"/>
        <geometry>
          <cylinder radius="${radius}" length="${width}"/>
        </geometry>
        <material name="dark_grey">
          <color rgba="0.15 0.15 0.15 1.0"/>
        </material>
      </visual>

      <collision>
        <origin xyz="0 0 0" rpy="1.5708 0 0"/>
        <geometry>
          <cylinder radius="${radius}" length="${width}"/>
        </geometry>
      </collision>

      <inertial>
        <origin xyz="0 0 0" rpy="0 0 0"/>
        <mass value="${mass}"/>
        <inertia
          ixx="${mass * (3 * radius * radius + width * width) / 12.0}"
          ixy="0.0"
          ixz="0.0"
          iyy="${0.5 * mass * radius * radius}"
          iyz="0.0"
          izz="${mass * (3 * radius * radius + width * width) / 12.0}"/>
      </inertial>
    </link>

    <joint name="${prefix}_wheel_joint" type="continuous">
      <parent link="base_link"/>
      <child link="${prefix}_wheel_link"/>
      <origin xyz="${x} ${y} ${z}" rpy="0 0 0"/>
      <axis xyz="0 1 0"/>
    </joint>
  </xacro:macro>

  <xacro:macro name="caster_wheel" params="prefix x y z radius mass">
    <link name="${prefix}_caster_link">
      <visual>
        <origin xyz="0 0 0" rpy="0 0 0"/>
        <geometry>
          <sphere radius="${radius}"/>
        </geometry>
        <material name="silver">
          <color rgba="0.78 0.78 0.82 1.0"/>
        </material>
      </visual>

      <collision>
        <origin xyz="0 0 0" rpy="0 0 0"/>
        <geometry>
          <sphere radius="${radius}"/>
        </geometry>
      </collision>

      <inertial>
        <origin xyz="0 0 0" rpy="0 0 0"/>
        <mass value="${mass}"/>
        <inertia
          ixx="${0.4 * mass * radius * radius}"
          ixy="0.0"
          ixz="0.0"
          iyy="${0.4 * mass * radius * radius}"
          iyz="0.0"
          izz="${0.4 * mass * radius * radius}"/>
      </inertial>
    </link>

    <joint name="${prefix}_caster_joint" type="fixed">
      <parent link="base_link"/>
      <child link="${prefix}_caster_link"/>
      <origin xyz="${x} ${y} ${z}" rpy="0 0 0"/>
    </joint>
  </xacro:macro>
</robot>
